Workbook

Sheet Introduction
B1: Introduction | J1: Company: Bo & Vine - Eugene (Restaurant)
J4: Created By: Jameson Bortnem
B6: Navigation | F6: Situation
B7: =HYPERLINK("#'Dashboard'!A1","Inventory Overview → Dashboard ") -> Inventory Overview → Dashboard | F7: • Inventory was taken on paper and took over an hour to complete.
B8: =HYPERLINK("#'Inventory Status'!A1","Data Entry → Inventory Status") -> Data Entry → Inventory Status | F8: • The manager struggled to stay within the owners' budget on ingredient orders.
B9: =HYPERLINK("#'Expected Demand'!A1","Demand Multiplier → Expected Demand") -> Demand Multiplier → Expected Demand | F9: • Overstocking and ingredient waste were recurring problems.
B10: =HYPERLINK("#'Order Overview'!A1","Order Entry → Order Overview") -> Order Entry → Order Overview | F10: • This project was created to provide an accessible inventory and ordering system.
F11: • The system includes a dashboard, flags low stock, and order lists based on current inventory and expected demand.
F12: • The goal is to reduce waste by 15% and cut ordering costs by 15%.
B15: Last Updated | F15: How To Use
B16: 46126 | F16: 1. Update Current Quantity and the Last Updated date in the Inventory Status tab.
F17: 2. Update the Expected Demand Selector and the Last Updated date in the Expected Demand tab.
F18: 3. Update Order Price and Current Order Budget as needed in the Order Overview tab.
F19: 4. Update Order Quantity and the Last Updated date when creating the order list.
F20: 5. The dashboard automatically updates KPIs and charts.
F21: 6. Formulas added dynamically to new rows as needed.

Sheet Dashboard
B1: Inventory Dashboard
P2: Source Data As Of
P4: =Introduction!B16 -> 46126
B5: Company: Bo & Vine - Eugene
B7: Created By: Jameson Bortnem
B8: Total SKUs | E8: Total Target Quantity | H8: Total Stock Quantity | K8: Total Restock Quantity | N8: Target Quantity % | Q8: Restock Quantity %
B10: =COUNTA('Inventory Status'!B10:B26,'Inventory Status'!B30:B73,'Inventory Status'!B77:B158) -> 134 | E10: =SUM('Inventory Status'!F10:F26,'Inventory Status'!F30:F73,'Inventory Status'!F77:F158) -> 454.75 | H10: =SUM('Inventory Status'!E10:E26,'Inventory Status'!E30:E73,'Inventory Status'!E77:E158) -> 406 | K10: =SUM(SUMIF('Inventory Status'!G10:G26,">0"),SUMIF('Inventory Status'!G30:G73,">0"), SUMIF('Inventory Status'!G77:G158,">0")) -> 159 | N10: =COUNTIF('Inventory Status'!B10:H158,"YES") / (COUNTIF('Inventory Status'!B10:H158,"YES") + (COUNTIF('Inventory Status'!B10:H158,"NO"))) -> 0.43283582 | Q10: =COUNTIF('Inventory Status'!B10:H158,"NO") / (COUNTIF('Inventory Status'!B10:H158,"YES") + (COUNTIF('Inventory Status'!B10:H158,"NO"))) -> 0.56716418

Sheet Inventory Status
B1: Inventory Status
E3: Last Updated | G3: =Introduction!B16 -> 46126
B5: Company: Bo & Vine - Eugene
B7: Created By: Jameson Bortnem
B8: Frozen
B9: Item | C9: Category | D9: Unit Type | E9: Current Quantity | F9: Target Quantity | G9: Needed Quantity | H9: Restock?
B10: Brioche Buns | C10: Bread | D10: Box | E10: 3 | F10: 12 | G10: =MAX(0,frozeninventory[[#This Row],[Target Quantity]]-frozeninventory[[#This Row],[Current Quantity]]) -> 9 | H10: =IF(frozeninventory[[#This Row],[Needed Quantity]]>0, "YES","NO") -> YES
B11: White Bread | C11: Bread | D11: Bag | E11: 7 | F11: 8 | G11: =MAX(0,frozeninventory[[#This Row],[Target Quantity]]-frozeninventory[[#This Row],[Current Quantity]]) -> 1 | H11: =IF(frozeninventory[[#This Row],[Needed Quantity]]>0, "YES","NO") -> YES
B12: Gluten-Free Buns | C12: Bread | D12: Box | E12: 1 | F12: 2 | G12: =MAX(0,frozeninventory[[#This Row],[Target Quantity]]-frozeninventory[[#This Row],[Current Quantity]]) -> 1 | H12: =IF(frozeninventory[[#This Row],[Needed Quantity]]>0, "YES","NO") -> YES
B13: Mini Buns | C13: Bread | D13: Bag | E13: 3 | F13: 3 | G13: =MAX(0,frozeninventory[[#This Row],[Target Quantity]]-frozeninventory[[#This Row],[Current Quantity]]) -> 0 | H13: =IF(frozeninventory[[#This Row],[Needed Quantity]]>0, "YES","NO") -> NO
B14: Lemonade Concentrate | C14: Drink | D14: Bottle | E14: 12 | F14: 10 | G14: =MAX(0,frozeninventory[[#This Row],[Target Quantity]]-frozeninventory[[#This Row],[Current Quantity]]) -> 0 | H14: =IF(frozeninventory[[#This Row],[Needed Quantity]]>0, "YES","NO") -> NO
B15: Sweet Potato Fries | C15: Fry | D15: Box | E15: 1 | F15: 5 | G15: =MAX(0,frozeninventory[[#This Row],[Target Quantity]]-frozeninventory[[#This Row],[Current Quantity]]) -> 4 | H15: =IF(frozeninventory[[#This Row],[Needed Quantity]]>0, "YES","NO") -> YES
B16: Chocolate Ice Cream | C16: Ice Cream | D16: Tub | E16: 1 | F16: 3 | G16: =MAX(0,frozeninventory[[#This Row],[Target Quantity]]-frozeninventory[[#This Row],[Current Quantity]]) -> 2 | H16: =IF(frozeninventory[[#This Row],[Needed Quantity]]>0, "YES","NO") -> YES
B17: Vanilla Ice Cream | C17: Ice Cream | D17: Tub | E17: 2 | F17: 3 | G17: =MAX(0,frozeninventory[[#This Row],[Target Quantity]]-frozeninventory[[#This Row],[Current Quantity]]) -> 1 | H17: =IF(frozeninventory[[#This Row],[Needed Quantity]]>0, "YES","NO") -> YES
B18: Chicken Breast | C18: Meat | D18: Box | E18: 0 | F18: 8 | G18: =MAX(0,frozeninventory[[#This Row],[Target Quantity]]-frozeninventory[[#This Row],[Current Quantity]]) -> 8 | H18: =IF(frozeninventory[[#This Row],[Needed Quantity]]>0, "YES","NO") -> YES
B19: Bean Patties | C19: Misc | D19: Box | E19: 0 | F19: 2 | G19: =MAX(0,frozeninventory[[#This Row],[Target Quantity]]-frozeninventory[[#This Row],[Current Quantity]]) -> 2 | H19: =IF(frozeninventory[[#This Row],[Needed Quantity]]>0, "YES","NO") -> YES
B20: Corn | C20: Produce | D20: Bag | E20: 8 | F20: 6 | G20: =MAX(0,frozeninventory[[#This Row],[Target Quantity]]-frozeninventory[[#This Row],[Current Quantity]]) -> 0 | H20: =IF(frozeninventory[[#This Row],[Needed Quantity]]>0, "YES","NO") -> NO
B21: Habañero Peppers | C21: Produce | D21: Box | E21: 1 | F21: 1 | G21: =MAX(0,frozeninventory[[#This Row],[Target Quantity]]-frozeninventory[[#This Row],[Current Quantity]]) -> 0 | H21: =IF(frozeninventory[[#This Row],[Needed Quantity]]>0, "YES","NO") -> NO
B22: Strawberry | C22: Produce | D22: Bottle | E22: 8 | F22: 3 | G22: =MAX(0,frozeninventory[[#This Row],[Target Quantity]]-frozeninventory[[#This Row],[Current Quantity]]) -> 0 | H22: =IF(frozeninventory[[#This Row],[Needed Quantity]]>0, "YES","NO") -> NO
B28: Refridgerated
B29: Item | C29: Category | D29: Unit Type | E29: Current Quantity | F29: Target Quantity | G29: Quantity Needed | H29: Reorder?
B30: Butter | C30: Dairy | D30: Stick | E30: 20 | F30: 10 | G30: =MAX(0,refridgeratedinventory[[#This Row],[Target Quantity]]-refridgeratedinventory[[#This Row],[Current Quantity]]) -> 0 | H30: =IF(refridgeratedinventory[[#This Row],[Quantity Needed]]>0, "YES","NO") -> NO
B31: Whipped Cream | C31: Dairy | D31: Can | E31: 15 | F31: 10 | G31: =MAX(0,refridgeratedinventory[[#This Row],[Target Quantity]]-refridgeratedinventory[[#This Row],[Current Quantity]]) -> 0 | H31: =IF(refridgeratedinventory[[#This Row],[Quantity Needed]]>0, "YES","NO") -> NO
B32: Heavy Whipping Cream | C32: Dairy | D32: Carton | E32: 0 | F32: 1 | G32: =MAX(0,refridgeratedinventory[[#This Row],[Target Quantity]]-refridgeratedinventory[[#This Row],[Current Quantity]]) -> 1 | H32: =IF(refridgeratedinventory[[#This Row],[Quantity Needed]]>0, "YES","NO") -> YES
B33: Milk | C33: Dairy | D33: Carton | E33: 2 | F33: 4 | G33: =MAX(0,refridgeratedinventory[[#This Row],[Target Quantity]]-refridgeratedinventory[[#This Row],[Current Quantity]]) -> 2 | H33: =IF(refridgeratedinventory[[#This Row],[Quantity Needed]]>0, "YES","NO") -> YES
B34: Sliced Cheddar Cheese | C34: Dairy | D34: Bag | E34: 4 | F34: 8 | G34: =MAX(0,refridgeratedinventory[[#This Row],[Target Quantity]]-refridgeratedinventory[[#This Row],[Current Quantity]]) -> 4 | H34: =IF(refridgeratedinventory[[#This Row],[Quantity Needed]]>0, "YES","NO") -> YES
B35: Bleu Cheese | C35: Dairy | D35: Bag | E35: 2 | F35: 3 | G35: =MAX(0,refridgeratedinventory[[#This Row],[Target Quantity]]-refridgeratedinventory[[#This Row],[Current Quantity]]) -> 1 | H35: =IF(refridgeratedinventory[[#This Row],[Quantity Needed]]>0, "YES","NO") -> YES
B36: Shredded Cheddar Cheese | C36: Dairy | D36: Bag | E36: 1 | F36: 3 | G36: =MAX(0,refridgeratedinventory[[#This Row],[Target Quantity]]-refridgeratedinventory[[#This Row],[Current Quantity]]) -> 2 | H36: =IF(refridgeratedinventory[[#This Row],[Quantity Needed]]>0, "YES","NO") -> YES
B37: Sliced Pepperjack Cheese | C37: Dairy | D37: Bag | E37: 1 | F37: 6 | G37: =MAX(0,refridgeratedinventory[[#This Row],[Target Quantity]]-refridgeratedinventory[[#This Row],[Current Quantity]]) -> 5 | H37: =IF(refridgeratedinventory[[#This Row],[Quantity Needed]]>0, "YES","NO") -> YES
B38: Goat Cheese | C38: Dairy | D38: Container | E38: 3 | F38: 3 | G38: =MAX(0,refridgeratedinventory[[#This Row],[Target Quantity]]-refridgeratedinventory[[#This Row],[Current Quantity]]) -> 0 | H38: =IF(refridgeratedinventory[[#This Row],[Quantity Needed]]>0, "YES","NO") -> NO
B39: Shredded Parmesan Cheese | C39: Dairy | D39: Bag | E39: 1 | F39: 3 | G39: =MAX(0,refridgeratedinventory[[#This Row],[Target Quantity]]-refridgeratedinventory[[#This Row],[Current Quantity]]) -> 2 | H39: =IF(refridgeratedinventory[[#This Row],[Quantity Needed]]>0, "YES","NO") -> YES
B40: Swiss Cheese | C40: Dairy | D40: Bag | E40: 3 | F40: 3 | G40: =MAX(0,refridgeratedinventory[[#This Row],[Target Quantity]]-refridgeratedinventory[[#This Row],[Current Quantity]]) -> 0 | H40: =IF(refridgeratedinventory[[#This Row],[Quantity Needed]]>0, "YES","NO") -> NO
B41: Coffee Concentrate | C41: Drink | D41: Bottle | E41: 11 | F41: 12 | G41: =MAX(0,refridgeratedinventory[[#This Row],[Target Quantity]]-refridgeratedinventory[[#This Row],[Current Quantity]]) -> 1 | H41: =IF(refridgeratedinventory[[#This Row],[Quantity Needed]]>0, "YES","NO") -> YES
... B70: Pesto | C70: Sauce | D70: Container | E70: 4 | F70: 2 | G70: =MAX(0,refridgeratedinventory[[#This Row],[Target Quantity]]-refridgeratedinventory[[#This Row],[Current Quantity]]) -> 0 | H70: =IF(refridgeratedinventory[[#This Row],[Quantity Needed]]>0, "YES","NO") -> NO
B75: Dry
B76: Item | C76: Category | D76: Unit Type | E76: Current Quantity | F76: Target Quantity | G76: Quantity Needed | H76: Reorder?
B77: Griddle Pads | C77: Cleaning | D77: Pad | E77: 15 | F77: 10 | G77: =MAX(0,dryinventory[[#This Row],[Target Quantity]]-dryinventory[[#This Row],[Current Quantity]]) -> 0 | H77: =IF(dryinventory[[#This Row],[Quantity Needed]]>0, "YES","NO") -> NO
B78: Floor Cleaner | C78: Cleaning | D78: Bottle | E78: 3 | F78: 1 | G78: =MAX(0,dryinventory[[#This Row],[Target Quantity]]-dryinventory[[#This Row],[Current Quantity]]) -> 0 | H78: =IF(dryinventory[[#This Row],[Quantity Needed]]>0, "YES","NO") -> NO
B79: Windex | C79: Cleaning | D79: Bottle | E79: 3 | F79: 1 | G79: =MAX(0,dryinventory[[#This Row],[Target Quantity]]-dryinventory[[#This Row],[Current Quantity]]) -> 0 | H79: =IF(dryinventory[[#This Row],[Quantity Needed]]>0, "YES","NO") -> NO
B80: Degreaser | C80: Cleaning | D80: Bottle | E80: 2 | F80: 2 | G80: =MAX(0,dryinventory[[#This Row],[Target Quantity]]-dryinventory[[#This Row],[Current Quantity]]) -> 0 | H80: =IF(dryinventory[[#This Row],[Quantity Needed]]>0, "YES","NO") -> NO
...

Sheet Expected Demand
B1: Expected Demand
B5: Company: Bo & Vine - Eugene
B7: Created By: Jameson Bortnem
B8: Last Updated | C8: =Introduction!B16 -> 46126
B13: Expected Demand Selector | C13: Normal
B18: Expected Demand Overview
B20: Demand Level | C20: Multiplier
B21: Normal | C21: 1
B22: High | C22: 1.5
B23: Very High | C23: 2

Sheet Order Overview
B1: Order Overview
E2: Last Updated | G2: =Introduction!B16 -> 46126
E5: Current Order Budget | G5: 6500
B7: Company: Bo & Vine - Eugene | E7: Total Order Price | G7: =SUM(H28,H77,H164) -> 6411.24
B8: Created By: Jameson Bortnem
B9: Frozen
B10: Items Needed | C10: Category | D10: Unit Type | E10: Needed Quantity (W/ Multiplier) | F10: Order Price | G10: Order Quantity | H10: Line Price
B11: =IF('Inventory Status'!B10="","",'Inventory Status'!B10) -> Brioche Buns | C11: =IF('Inventory Status'!C10="","",'Inventory Status'!C10) -> Bread | D11: =IF('Inventory Status'!D10="","",'Inventory Status'!D10) -> Box | E11: =IF('Inventory Status'!G10="","",'Inventory Status'!G10)*_xlfn.XLOOKUP('Expected Demand'!$C$13,Table33[Demand Level],Table33[Multiplier]) -> 9 | F11: 32.76 | G11: 14 | H11: =IF(frozenorder[[#This Row],[Order Price]]*frozenorder[[#This Row],[Order Quantity]]=0, "",frozenorder[[#This Row],[Order Price]]*frozenorder[[#This Row],[Order Quantity]]) -> 458.64
B12: =IF('Inventory Status'!B11="","",'Inventory Status'!B11) -> White Bread | C12: =IF('Inventory Status'!C11="","",'Inventory Status'!C11) -> Bread | D12: =IF('Inventory Status'!D11="","",'Inventory Status'!D11) -> Bag | E12: =IF('Inventory Status'!G11="","",'Inventory Status'!G11)*_xlfn.XLOOKUP('Expected Demand'!$C$13,Table33[Demand Level],Table33[Multiplier]) -> 1 | F12: 53.42 | G12: 2 | H12: =IF(frozenorder[[#This Row],[Order Price]]*frozenorder[[#This Row],[Order Quantity]]=0, "",frozenorder[[#This Row],[Order Price]]*frozenorder[[#This Row],[Order Quantity]]) -> 106.84
B13: =IF('Inventory Status'!B12="","",'Inventory Status'!B12) -> Gluten-Free Buns | C13: =IF('Inventory Status'!C12="","",'Inventory Status'!C12) -> Bread | D13: =IF('Inventory Status'!D12="","",'Inventory Status'!D12) -> Box | E13: =IF('Inventory Status'!G12="","",'Inventory Status'!G12)*_xlfn.XLOOKUP('Expected Demand'!$C$13,Table33[Demand Level],Table33[Multiplier]) -> 1 | F13: 36.72 | G13: 2 | H13: =IF(frozenorder[[#This Row],[Order Price]]*frozenorder[[#This Row],[Order Quantity]]=0, "",frozenorder[[#This Row],[Order Price]]*frozenorder[[#This Row],[Order Quantity]]) -> 73.44
B14: =IF('Inventory Status'!B13="","",'Inventory Status'!B13) -> Mini Buns | C14: =IF('Inventory Status'!C13="","",'Inventory Status'!C13) -> Bread | D14: =IF('Inventory Status'!D13="","",'Inventory Status'!D13) -> Bag | E14: =IF('Inventory Status'!G13="","",'Inventory Status'!G13)*_xlfn.XLOOKUP('Expected Demand'!$C$13,Table33[Demand Level],Table33[Multiplier]) -> 0 | F14: 45.98 | G14: 0 | H14: =IF(frozenorder[[#This Row],[Order Price]]*frozenorder[[#This Row],[Order Quantity]]=0, "",frozenorder[[#This Row],[Order Price]]*frozenorder[[#This Row],[Order Quantity]])
B15: =IF('Inventory Status'!B14="","",'Inventory Status'!B14) -> Lemonade Concentrate | C15: =IF('Inventory Status'!C14="","",'Inventory Status'!C14) -> Drink | D15: =IF('Inventory Status'!D14="","",'Inventory Status'!D14) -> Bottle | E15: =IF('Inventory Status'!G14="","",'Inventory Status'!G14)*_xlfn.XLOOKUP('Expected Demand'!$C$13,Table33[Demand Level],Table33[Multiplier]) -> 0 | F15: 46.82 | G15: 0 | H15: =IF(frozenorder[[#This Row],[Order Price]]*frozenorder[[#This Row],[Order Quantity]]=0, "",frozenorder[[#This Row],[Order Price]]*frozenorder[[#This Row],[Order Quantity]])
B16: =IF('Inventory Status'!B15="","",'Inventory Status'!B15) -> Sweet Potato Fries | C16: =IF('Inventory Status'!C15="","",'Inventory Status'!C15) -> Fry | D16: =IF('Inventory Status'!D15="","",'Inventory Status'!D15) -> Box | E16: =IF('Inventory Status'!G15="","",'Inventory Status'!G15)*_xlfn.XLOOKUP('Expected Demand'!$C$13,Table33[Demand Level],Table33[Multiplier]) -> 4 | F16: 41.25 | G16: 6 | H16: =IF(frozenorder[[#This Row],[Order Price]]*frozenorder[[#This Row],[Order Quantity]]=0, "",frozenorder[[#This Row],[Order Price]]*frozenorder[[#This Row],[Order Quantity]]) -> 247.5
B17: =IF('Inventory Status'!B16="","",'Inventory Status'!B16) -> Chocolate Ice Cream | C17: =IF('Inventory Status'!C16="","",'Inventory Status'!C16) -> Ice Cream | D17: =IF('Inventory Status'!D16="","",'Inventory Status'!D16) -> Tub | E17: =IF('Inventory Status'!G16="","",'Inventory Status'!G16)*_xlfn.XLOOKUP('Expected Demand'!$C$13,Table33[Demand Level],Table33[Multiplier]) -> 2 | F17: 27.92 | G17: 3 | H17: =IF(frozenorder[[#This Row],[Order Price]]*frozenorder[[#This Row],[Order Quantity]]=0, "",frozenorder[[#This Row],[Order Price]]*frozenorder[[#This Row],[Order Quantity]]) -> 83.76
B18: =IF('Inventory Status'!B17="","",'Inventory Status'!B17) -> Vanilla Ice Cream | C18: =IF('Inventory Status'!C17="","",'Inventory Status'!C17) -> Ice Cream | D18: =IF('Inventory Status'!D17="","",'Inventory Status'!D17) -> Tub | E18: =IF('Inventory Status'!G17="","",'Inventory Status'!G17)*_xlfn.XLOOKUP('Expected Demand'!$C$13,Table33[Demand Level],Table33[Multiplier]) -> 1 | F18: 30.99 | G18: 2 | H18: =IF(frozenorder[[#This Row],[Order Price]]*frozenorder[[#This Row],[Order Quantity]]=0, "",frozenorder[[#This Row],[Order Price]]*frozenorder[[#This Row],[Order Quantity]]) -> 61.98
B19: =IF('Inventory Status'!B18="","",'Inventory Status'!B18) -> Chicken Breast | C19: =IF('Inventory Status'!C18="","",'Inventory Status'!C18) -> Meat | D19: =IF('Inventory Status'!D18="","",'Inventory Status'!D18) -> Box | E19: =IF('Inventory Status'!G18="","",'Inventory Status'!G18)*_xlfn.XLOOKUP('Expected Demand'!$C$13,Table33[Demand Level],Table33[Multiplier]) -> 8 | F19: 43.14 | G19: 12 | H19: =IF(frozenorder[[#This Row],[Order Price]]*frozenorder[[#This Row],[Order Quantity]]=0, "",frozenorder[[#This Row],[Order Price]]*frozenorder[[#This Row],[Order Quantity]]) -> 517.68
B20: =IF('Inventory Status'!B19="","",'Inventory Status'!B19) -> Bean Patties | C20: =IF('Inventory Status'!C19="","",'Inventory Status'!C19) -> Misc | D20: =IF('Inventory Status'!D19="","",'Inventory Status'!D19) -> Box | E20: =IF('Inventory Status'!G19="","",'Inventory Status'!G19)*_xlfn.XLOOKUP('Expected Demand'!$C$13,Table33[Demand Level],Table33[Multiplier]) -> 2 | F20: 51.04 | G20: 3 | H20: =IF(frozenorder[[#This Row],[Order Price]]*frozenorder[[#This Row],[Order Quantity]]=0, "",frozenorder[[#This Row],[Order Price]]*frozenorder[[#This Row],[Order Quantity]]) -> 153.12
B21: =IF('Inventory Status'!B20="","",'Inventory Status'!B20) -> Corn | C21: =IF('Inventory Status'!C20="","",'Inventory Status'!C20) -> Produce | D21: =IF('Inventory Status'!D20="","",'Inventory Status'!D20) -> Bag | E21: =IF('Inventory Status'!G20="","",'Inventory Status'!G20)*_xlfn.XLOOKUP('Expected Demand'!$C$13,Table33[Demand Level],Table33[Multiplier]) -> 0 | F21: 23.45 | G21: 0 | H21: =IF(frozenorder[[#This Row],[Order Price]]*frozenorder[[#This Row],[Order Quantity]]=0, "",frozenorder[[#This Row],[Order Price]]*frozenorder[[#This Row],[Order Quantity]])
B22: =IF('Inventory Status'!B21="","",'Inventory Status'!B21) -> Habañero Peppers | C22: =IF('Inventory Status'!C21="","",'Inventory Status'!C21) -> Produce | D22: =IF('Inventory Status'!D21="","",'Inventory Status'!D21) -> Box | E22: =IF('Inventory Status'!G21="","",'Inventory Status'!G21)*_xlfn.XLOOKUP('Expected Demand'!$C$13,Table33[Demand Level],Table33[Multiplier]) -> 0 | F22: 34.87 | G22: 0 | H22: =IF(frozenorder[[#This Row],[Order Price]]*frozenorder[[#This Row],[Order Quantity]]=0, "",frozenorder[[#This Row],[Order Price]]*frozenorder[[#This Row],[Order Quantity]])
B23: =IF('Inventory Status'!B22="","",'Inventory Status'!B22) -> Strawberry | C23: =IF('Inventory Status'!C22="","",'Inventory Status'!C22) -> Produce | D23: =IF('Inventory Status'!D22="","",'Inventory Status'!D22) -> Bottle | E23: =IF('Inventory Status'!G22="","",'Inventory Status'!G22)*_xlfn.XLOOKUP('Expected Demand'!$C$13,Table33[Demand Level],Table33[Multiplier]) -> 0 | F23: 108.4 | G23: 0 | H23: =IF(frozenorder[[#This Row],[Order Price]]*frozenorder[[#This Row],[Order Quantity]]=0, "",frozenorder[[#This Row],[Order Price]]*frozenorder[[#This Row],[Order Quantity]])
B24: =IF('Inventory Status'!B23="","",'Inventory Status'!B23) | C24: =IF('Inventory Status'!C23="","",'Inventory Status'!C23) | D24: =IF('Inventory Status'!D23="","",'Inventory Status'!D23) | H24: =IF(frozenorder[[#This Row],[Order Price]]*frozenorder[[#This Row],[Order Quantity]]=0, "",frozenorder[[#This Row],[Order Price]]*frozenorder[[#This Row],[Order Quantity]])
B25: =IF('Inventory Status'!B24="","",'Inventory Status'!B24) | C25: =IF('Inventory Status'!C24="","",'Inventory Status'!C24) | D25: =IF('Inventory Status'!D24="","",'Inventory Status'!D24) | H25: =IF(frozenorder[[#This Row],[Order Price]]*frozenorder[[#This Row],[Order Quantity]]=0, "",frozenorder[[#This Row],[Order Price]]*frozenorder[[#This Row],[Order Quantity]])
B26: =IF('Inventory Status'!B25="","",'Inventory Status'!B25) | C26: =IF('Inventory Status'!C25="","",'Inventory Status'!C25) | D26: =IF('Inventory Status'!D25="","",'Inventory Status'!D25) | H26: =IF(frozenorder[[#This Row],[Order Price]]*frozenorder[[#This Row],[Order Quantity]]=0, "",frozenorder[[#This Row],[Order Price]]*frozenorder[[#This Row],[Order Quantity]])
B27: =IF('Inventory Status'!B26="","",'Inventory Status'!B26) | C27: =IF('Inventory Status'!C26="","",'Inventory Status'!C26) | D27: =IF('Inventory Status'!D26="","",'Inventory Status'!D26) | H27: =IF(frozenorder[[#This Row],[Order Price]]*frozenorder[[#This Row],[Order Quantity]]=0, "",frozenorder[[#This Row],[Order Price]]*frozenorder[[#This Row],[Order Quantity]])
G28: Frozen Total | H28: =SUM(frozenorder[Line Price]) -> 1702.96
B31: Refridgerated
B32: Items Needed | C32: Category | D32: Unit Type | E32: Needed Quantity (W/ Multiplier) | F32: Order Price | G32: Order Quantity | H32: Line Price
B33: =IF('Inventory Status'!B30="","",'Inventory Status'!B30) -> Butter | C33: =IF('Inventory Status'!C30="","",'Inventory Status'!C30) -> Dairy | D33: =IF('Inventory Status'!D30="","",'Inventory Status'!D30) -> Stick | E33: =IF('Inventory Status'!G30*_xlfn.XLOOKUP('Expected Demand'!$C$13,Table33[Demand Level],Table33[Multiplier])="","",'Inventory Status'!G30*_xlfn.XLOOKUP('Expected Demand'!$C$13,Table33[Demand Level],Table33[Multiplier])) -> 0 | F33: 32.34 | G33: 0 | H33: =IF(refridgeratedorder[[#This Row],[Order Price]]*refridgeratedorder[[#This Row],[Order Quantity]]=0, "",refridgeratedorder[[#This Row],[Order Price]]*refridgeratedorder[[#This Row],[Order Quantity]])
B34: =IF('Inventory Status'!B31="","",'Inventory Status'!B31) -> Whipped Cream | C34: =IF('Inventory Status'!C31="","",'Inventory Status'!C31) -> Dairy | D34: =IF('Inventory Status'!D31="","",'Inventory Status'!D31) -> Can | E34: =IF('Inventory Status'!G31*_xlfn.XLOOKUP('Expected Demand'!$C$13,Table33[Demand Level],Table33[Multiplier])="","",'Inventory Status'!G31*_xlfn.XLOOKUP('Expected Demand'!$C$13,Table33[Demand Level],Table33[Multiplier])) -> 0 | F34: 22.45 | G34: 0 | H34: =IF(refridgeratedorder[[#This Row],[Order Price]]*refridgeratedorder[[#This Row],[Order Quantity]]=0, "",refridgeratedorder[[#This Row],[Order Price]]*refridgeratedorder[[#This Row],[Order Quantity]])
B35: =IF('Inventory Status'!B32="","",'Inventory Status'!B32) -> Heavy Whipping Cream | C35: =IF('Inventory Status'!C32="","",'Inventory Status'!C32) -> Dairy | D35: =IF('Inventory Status'!D32="","",'Inventory Status'!D32) -> Carton | E35: =IF('Inventory Status'!G32*_xlfn.XLOOKUP('Expected Demand'!$C$13,Table33[Demand Level],Table33[Multiplier])="","",'Inventory Status'!G32*_xlfn.XLOOKUP('Expected Demand'!$C$13,Table33[Demand Level],Table33[Multiplier])) -> 1 | F35: 13.66 | G35: 2 | H35: =IF(refridgeratedorder[[#This Row],[Order Price]]*refridgeratedorder[[#This Row],[Order Quantity]]=0, "",refridgeratedorder[[#This Row],[Order Price]]*refridgeratedorder[[#This Row],[Order Quantity]]) -> 27.32
B36: =IF('Inventory Status'!B33="","",'Inventory Status'!B33) -> Milk | C36: =IF('Inventory Status'!C33="","",'Inventory Status'!C33) -> Dairy | D36: =IF('Inventory Status'!D33="","",'Inventory Status'!D33) -> Carton | E36: =IF('Inventory Status'!G33*_xlfn.XLOOKUP('Expected Demand'!$C$13,Table33[Demand Level],Table33[Multiplier])="","",'Inventory Status'!G33*_xlfn.XLOOKUP('Expected Demand'!$C$13,Table33[Demand Level],Table33[Multiplier])) -> 2 | F36: 12.07 | G36: 3 | H36: =IF(refridgeratedorder[[#This Row],[Order Price]]*refridgeratedorder[[#This Row],[Order Quantity]]=0, "",refridgeratedorder[[#This Row],[Order Price]]*refridgeratedorder[[#This Row],[Order Quantity]]) -> 36.21
B37: =IF('Inventory Status'!B34="","",'Inventory Status'!B34) -> Sliced Cheddar Cheese | C37: =IF('Inventory Status'!C34="","",'Inventory Status'!C34) -> Dairy | D37: =IF('Inventory Status'!D34="","",'Inventory Status'!D34) -> Bag | E37: =IF('Inventory Status'!G34*_xlfn.XLOOKUP('Expected Demand'!$C$13,Table33[Demand Level],Table33[Multiplier])="","",'Inventory Status'!G34*_xlfn.XLOOKUP('Expected Demand'!$C$13,Table33[Demand Level],Table33[Multiplier])) -> 4 | F37: 29.26 | G37: 6 | H37: =IF(refridgeratedorder[[#This Row],[Order Price]]*refridgeratedorder[[#This Row],[Order Quantity]]=0, "",refridgeratedorder[[#This Row],[Order Price]]*refridgeratedorder[[#This Row],[Order Quantity]]) -> 175.56
B38: =IF('Inventory Status'!B35="","",'Inventory Status'!B35) -> Bleu Cheese | C38: =IF('Inventory Status'!C35="","",'Inventory Status'!C35) -> Dairy | D38: =IF('Inventory Status'!D35="","",'Inventory Status'!D35) -> Bag | E38: =IF('Inventory Status'!G35*_xlfn.XLOOKUP('Expected Demand'!$C$13,Table33[Demand Level],Table33[Multiplier])="","",'Inventory Status'!G35*_xlfn.XLOOKUP('Expected Demand'!$C$13,Table33[Demand Level],Table33[Multiplier])) -> 1 | F38: 22.72 | G38: 2 | H38: =IF(refridgeratedorder[[#This Row],[Order Price]]*refridgeratedorder[[#This Row],[Order Quantity]]=0, "",refridgeratedorder[[#This Row],[Order Price]]*refridgeratedorder[[#This Row],[Order Quantity]]) -> 45.44
B39: =IF('Inventory Status'!B36="","",'Inventory Status'!B36) -> Shredded Cheddar Cheese | C39: =IF('Inventory Status'!C36="","",'Inventory Status'!C36) -> Dairy | D39: =IF('Inventory Status'!D36="","",'Inventory Status'!D36) -> Bag | E39: =IF('Inventory Status'!G36*_xlfn.XLOOKUP('Expected Demand'!$C$13,Table33[Demand Level],Table33[Multiplier])="","",'Inventory Status'!G36*_xlfn.XLOOKUP('Expected Demand'!$C$13,Table33[Demand Level],Table33[Multiplier])) -> 2 | F39: 21.23 | G39: 3 | H39: =IF(refridgeratedorder[[#This Row],[Order Price]]*refridgeratedorder[[#This Row],[Order Quantity]]=0, "",refridgeratedorder[[#This Row],[Order Price]]*refridgeratedorder[[#This Row],[Order Quantity]]) -> 63.69
B40: =IF('Inventory Status'!B37="","",'Inventory Status'!B37) -> Sliced Pepperjack Cheese | C40: =IF('Inventory Status'!C37="","",'Inventory Status'!C37) -> Dairy | D40: =IF('Inventory Status'!D37="","",'Inventory Status'!D37) -> Bag | E40: =IF('Inventory Status'!G37*_xlfn.XLOOKUP('Expected Demand'!$C$13,Table33[Demand Level],Table33[Multiplier])="","",'Inventory Status'!G37*_xlfn.XLOOKUP('Expected Demand'!$C$13,Table33[Demand Level],Table33[Multiplier])) -> 5 | F40: 34.11 | G40: 8 | H40: =IF(refridgeratedorder[[#This Row],[Order Price]]*refridgeratedorder[[#This Row],[Order Quantity]]=0, "",refridgeratedorder[[#This Row],[Order Price]]*refridgeratedorder[[#This Row],[Order Quantity]]) -> 272.88
B41: =IF('Inventory Status'!B38="","",'Inventory Status'!B38) -> Goat Cheese | C41: =IF('Inventory Status'!C38="","",'Inventory Status'!C38) -> Dairy | D41: =IF('Inventory Status'!D38="","",'Inventory Status'!D38) -> Container | E41: =IF('Inventory Status'!G38*_xlfn.XLOOKUP('Expected Demand'!$C$13,Table33[Demand Level],Table33[Multiplier])="","",'Inventory Status'!G38*_xlfn.XLOOKUP('Expected Demand'!$C$13,Table33[Demand Level],Table33[Multiplier])) -> 0 | F41: 33.37 | G41: 0 | H41: =IF(refridgeratedorder[[#This Row],[Order Price]]*refridgeratedorder[[#This Row],[Order Quantity]]=0, "",refridgeratedorder[[#This Row],[Order Price]]*refridgeratedorder[[#This Row],[Order Quantity]])
B42: =IF('Inventory Status'!B39="","",'Inventory Status'!B39) -> Shredded Parmesan Cheese | C42: =IF('Inventory Status'!C39="","",'Inventory Status'!C39) -> Dairy | D42: =IF('Inventory Status'!D39="","",'Inventory Status'!D39) -> Bag | E42: =IF('Inventory Status'!G39*_xlfn.XLOOKUP('Expected Demand'!$C$13,Table33[Demand Level],Table33[Multiplier])="","",'Inventory Status'!G39*_xlfn.XLOOKUP('Expected Demand'!$C$13,Table33[Demand Level],Table33[Multiplier])) -> 2 | F42: 41.51 | G42: 3 | H42: =IF(refridgeratedorder[[#This Row],[Order Price]]*refridgeratedorder[[#This Row],[Order Quantity]]=0, "",refridgeratedorder[[#This Row],[Order Price]]*refridgeratedorder[[#This Row],[Order Quantity]]) -> 124.53
B43: =IF('Inventory Status'!B40="","",'Inventory Status'!B40) -> Swiss Cheese | C43: =IF('Inventory Status'!C40="","",'Inventory Status'!C40) -> Dairy | D43: =IF('Inventory Status'!D40="","",'Inventory Status'!D40) -> Bag | E43: =IF('Inventory Status'!G40*_xlfn.XLOOKUP('Expected Demand'!$C$13,Table33[Demand Level],Table33[Multiplier])="","",'Inventory Status'!G40*_xlfn.XLOOKUP('Expected Demand'!$C$13,Table33[Demand Level],Table33[Multiplier])) -> 0 | F43: 23.12 | G43: 0 | H43: =IF(refridgeratedorder[[#This Row],[Order Price]]*refridgeratedorder[[#This Row],[Order Quantity]]=0, "",refridgeratedorder[[#This Row],[Order Price]]*refridgeratedorder[[#This Row],[Order Quantity]])
B44: =IF('Inventory Status'!B41="","",'Inventory Status'!B41) -> Coffee Concentrate | C44: =IF('Inventory Status'!C41="","",'Inventory Status'!C41) -> Drink | D44: =IF('Inventory Status'!D41="","",'Inventory Status'!D41) -> Bottle | E44: =IF('Inventory Status'!G41*_xlfn.XLOOKUP('Expected Demand'!$C$13,Table33[Demand Level],Table33[Multiplier])="","",'Inventory Status'!G41*_xlfn.XLOOKUP('Expected Demand'!$C$13,Table33[Demand Level],Table33[Multiplier])) -> 1 | F44: 36.72 | G44: 2 | H44: =IF(refridgeratedorder[[#This Row],[Order Price]]*refridgeratedorder[[#This Row],[Order Quantity]]=0, "",refridgeratedorder[[#This Row],[Order Price]]*refridgeratedorder[[#This Row],[Order Quantity]]) -> 73.44
... B73: =IF('Inventory Status'!B70="","",'Inventory Status'!B70) -> Pesto | C73: =IF('Inventory Status'!C70="","",'Inventory Status'!C70) -> Sauce | D73: =IF('Inventory Status'!D70="","",'Inventory Status'!D70) -> Container | E73: =IF('Inventory Status'!G70*_xlfn.XLOOKUP('Expected Demand'!$C$13,Table33[Demand Level],Table33[Multiplier])="","",'Inventory Status'!G70*_xlfn.XLOOKUP('Expected Demand'!$C$13,Table33[Demand Level],Table33[Multiplier])) -> 0 | F73: 83.34 | G73: 0 | H73: =IF(refridgeratedorder[[#This Row],[Order Price]]*refridgeratedorder[[#This Row],[Order Quantity]]=0, "",refridgeratedorder[[#This Row],[Order Price]]*refridgeratedorder[[#This Row],[Order Quantity]])
...
