Workbook

Sheet Introduction
B1: PERSONAL FINANCIAL PLANNING CASE-STUDY
B2: A hypothetical-client financial planning workbook
B3: Prepared By: Jameson Bortnem
B4: Last Updated: September 2026 | Version: 1.0
B6: Workbook Purpose | D6: Workbook Map
B8: This workbook evaluates the current financial position of a hypothetical client and develops a practical plan for cash flow, emergency savings, debt repayment, and financial priorities. It connects assumptions, current balances, budgeted activity, and payoff projections into a single planning dashboard. The model is designed to demonstrate Excel-based financial-planning analysis for portfolio and educational purposes. | D8: =HYPERLINK("#'Introduction'!A1","Introduction") -> Introduction | E8: Workbook purpose, instructions, and navigation
D10: =HYPERLINK("#'Client Profile'!A1","Client Profile") -> Client Profile | E10: Hypothetical client background, priorities, goals, and constraints
D12: =HYPERLINK("#'Key Assumptions'!A1","Key Asssumptions") -> Key Asssumptions | E12: Central model inputs, planning rules, and assumptions
B13: How To Use This Workbook
D14: =HYPERLINK("#'Financial Position'!A1","Financial Position") -> Financial Position | E14: Assets, liabilities, net worth, and key financial ratios
B15: 1. Review the Client Profile to understand the client’s background, priorities, goals, and constraints.
B16: 2. Update blue-font input cells in Key Assumptions to test a different scenario. | D16: =HYPERLINK("#'Cash-Flow & Budget'!A1","Cash-Flow & Budget") -> Cash-Flow & Budget | E16: Budgeted versus actual monthly income, spending, savings, and cash flow
B17: 3. Review Financial Position for assets, liabilities, net worth, and planning ratios.
B18: 4. Use Cash Flow & Budget to compare planned spending with actual monthly spending and identify monthly surplus or deficit. | D18: =HYPERLINK("#'Emergency Fund'!A1","Emergency Fund") -> Emergency Fund | E18: Reserve target, monthly contribution, progress, and projected completion date
B20: 5. Track the monthly emergency fund contribution and expected completion date in Emergency Fund. | D20: =HYPERLINK("#'Debt Payoff'!A1","Debt Payoff") -> Debt Payoff | E20: Debt-avalanche payoff order, balances, monthly schedule, interest, and milestones
B21: 6. Review the debt-avalanche plan in Debt Payoff, then use the Planning Dashboard for the primary recommendations and summary metrics.
D22: =HYPERLINK("#'Planning Dashboard'!A1","Planning Dashboard") -> Planning Dashboard | E22: Client-facing summary, KPIs, charts, and recommended actions
B24: Important Notes
B26: This workbook is an educational portfolio project based on a hypothetical client scenario. It is not individualized financial, investment, tax, or legal advice. All account balances, income, expenses, interest rates, investment assumptions, tax estimates, and projected dates are illustrative and may differ from real-world outcomes. Projections assume the stated inputs remain consistent; actual results may change because of spending, income, interest-rate, payment, or life-event changes.

Sheet Client Profile
B1: Client Profile
B2: Christopher Miller | C2: September 2026
B4: Client Summary
B5: Name | C5: Christopher Miller
B6: Age | C6: 32
B7: Location | C7: Portland, OR
B8: Occupation | C8: Marketing Manager
B9: Annual Gross Income | C9: 80000
B10: Marital Status | C10: Single
B11: Tax Filing Status | C11: Single
B12: Dependents | C12: None
B13: Pets | C13: None
B15: Goals
B16: Primary Goal | C16: Build a three-month emergency fund within 24 months
B17: Secondary Goal | C17: Pay off all debt within 5 years
B18: Long-Term Goal | C18: Begin consistent retirement saving at 8% of gross income
B20: Values, Concerns, & Behavior
B21: Primary Financial Concern | C21: No cash buffer for unexpected expenses
B22: Secondary Financial Concern | C22: High-interest credit card debt
B23: Main Priority | C23: Financial stability before aggressive investing
B24: Behavior | C24: Tends to overspend on discretionary categories
B25: Advising Preference | C25: Simple planning with clear steps
B27: Risk & Constraints
B28: Risk Tolerance | C28: Moderate
B29: Liquidity Need | C29: High until emergency fund is established
B30: Investment Comfort | C30: Prefers cash savings before additional market investments
B31: Debt Tolerance | C31: Low
B32: Primary Constraint | C32: Limited monthly cash-flow surplus
B33: Secondary Constraint | C33: Low retirement balance for age; high credit card APR
B35: Planning Scope
B36: • Current financial position review
B37: • Cash-flow & monthly-budget analysis
B38: • Emergency fund target
B39: • Debt payoff strategy
B40: • Planning dashboard & next actions

Sheet Key Assumptions
B1: Key Assumptions
B2: ='Client Profile'!B2 -> Christopher Miller | C2: ='Client Profile'!C2 -> September 2026
B4: Personal & Timeline
B5: Current Age | C5: ='Client Profile'!C6 -> 32
B6: Planning Start Year | C6: 2026
B7: Planning Horizon (Years) | C7: 33
B8: Desired Retirement Age | C8: 65
B9: Life Expectancy | C9: 90
B11: Income
B12: Annual Gross Income | C12: ='Client Profile'!C9 -> 80000
B13: Monthly Gross Income | C13: =C12/12 -> 6666.6667
B14: Effective Tax Rate | C14: 0.2
B15: Annual Net Income | C15: =C12*(1-C14) -> 64000
B16: Monthly Net Income | C16: =C15/12 -> 5333.3333
B17: Expected Annual Raise (%) | C17: 0.05
B18: Monthly Net Side Income | C18: 0
B20: Monthly Expenses
B21: Housing & Utilities | C21: 1700
B22: Groceries | C22: 500
B23: Transportation | C23: 450
B24: Health & Insurance | C24: 300
B25: Personal & Household | C25: 250
B26: Technology & Subscriptions | C26: 150
B27: Dining & Entertainment | C27: 250
B28: Minimum Debt Obligations | C28: 765
B29: Miscellaneous | C29: 250
B30: Total Monthly Expenses | C30: =SUM(C21:C29) -> 4615
B32: Savings & Goals
B33: Emergency Fund Month Target | C33: 3
B34: Emergency Fund Amount Target | C34: =MROUND(C33*C30,500) -> 14000
B35: Monthly Emergency Fund Contribution | C35: 500
B36: Retirement Savings Rate Target | C36: 0.08
B37: Monthly Retirement Contribution | C37: 0
B38: Extra Debt Payment | C38: 150
B39: Home Down-Payment Time Horizon (Years) | C39: 0
B41: Debt
B42: Debt Payoff Method | C42: Avalanche
B43: Payment Priority Rule | C43: Pay every required minimum → Send all extra debt funds to the card with the highest APR → Roll its payment to the next highest APR after paid off
B45: Planning
B46: General Inflation Rate | C46: 0.03
...

Sheet Financial Position
B1: Financial Position
B2: ='Client Profile'!B2 -> Christopher Miller | C2: ='Client Profile'!C2 -> September 2026
B4: Assets
B5: Category | C5: Name | D5: Current Balance
B6: Cash | C6: Checking | D6: 1250
B7: Cash | C7: Savings | D7: 800
B8: Cash | C8: Emergency Fund HYSA | D8: 2000
B9: Retirement | C9: 401(k) | D9: 12500
B10: Retirement | C10: Roth IRA | D10: 2500
B11: Investments | C11: Brokerage | D11: 0
B12: Personal Property | C12: Vehicle | D12: 11000
B13: Personal Property | C13: Home | D13: 0
B14: Total Assets | D14: =SUM(D6:D13) -> 30050
B16: Liabilities
B17: Category | C17: Creditor | D17: Current Balance | E17: APR | F17: Minimum Payment
B18: Credit Card | C18: Chase | D18: 5400 | E18: 0.2724 | F18: 165
B19: Credit Card | C19: Discover | D19: 3100 | E19: 0.2499 | F19: 95
B20: Credit Card | C20: Capital One | D20: 1850 | E20: 0.2299 | F20: 60
B21: Student Loan | C21: Aidvantage | D21: 14500 | E21: 0.0525 | F21: 160
B22: Auto Loan | C22: Wells Fargo | D22: 9800 | E22: 0.0649 | F22: 285
B23: Total Liabilities | D23: =SUM(D18:D22) -> 34650 | F23: =SUM(F18:F22) -> 765
B25: Net Worth Summary
B26: Total Assets | C26: =D14 -> 30050
B27: Total Liabilities | C27: =D23 -> 34650
B28: Net Worth | C28: =C26-C27 -> -4600
B29: Liquid Assets | C29: =SUM(D6:D8) -> 4050
B30: High-Interest Debt | C30: {=SUM(IF(E18:E22>0.099,D18:D22,0))} -> 10350
B32: Key Ratios
B33: Current Emergency Fund Months | C33: =D8/('Key Assumptions'!C30) -> 0.43336945
B34: Savings Rate | C34: ='Cash-Flow & Budget'!C29/'Cash-Flow & Budget'!C8 -> 0.121875
B35: Debt-To-Income Ratio | C35: =D23/'Key Assumptions'!C12 -> 0.433125
B36: Debt-To-Assets Ratio | C36: =D23/D14 -> 1.1530782
B37: High-Interest Debt Share | C37: =C30/D23 -> 0.2987013

Sheet Cash-Flow & Budget
B1: Cash Flow & Budget
B2: ='Client Profile'!B2 -> Christopher Miller | C2: ='Client Profile'!C2 -> September 2026
B4: Monthly Income
B5: Category | C5: Budgeted Amount | D5: Actual Amount | E5: Variance
B6: Net Income | C6: ='Key Assumptions'!C16 -> 5333.3333 | D6: 5333.33 | E6: =C6-D6 -> 0.0033333333
B7: Net Side Income | C7: ='Key Assumptions'!C18 -> 0 | D7: 75 | E7: =C7-D7 -> -75
B8: Total Monthly Net Income | C8: =SUM(C6:C7) -> 5333.3333 | D8: =SUM(D6:D7) -> 5408.33 | E8: =C8-D8 -> -74.996667
B10: Monthly Expenses
B11: Category | C11: Budgeted Amount | D11: Actual Amount | E11: Variance
B12: ='Key Assumptions'!B21 -> Housing & Utilities | C12: ='Key Assumptions'!C21 -> 1700 | D12: 1700 | E12: =C12-D12 -> 0
B13: ='Key Assumptions'!B22 -> Groceries | C13: ='Key Assumptions'!C22 -> 500 | D13: 525 | E13: =C13-D13 -> -25
B14: ='Key Assumptions'!B23 -> Transportation | C14: ='Key Assumptions'!C23 -> 450 | D14: 460 | E14: =C14-D14 -> -10
B15: ='Key Assumptions'!B24 -> Health & Insurance | C15: ='Key Assumptions'!C24 -> 300 | D15: 295 | E15: =C15-D15 -> 5
B16: ='Key Assumptions'!B25 -> Personal & Household | C16: ='Key Assumptions'!C25 -> 250 | D16: 265 | E16: =C16-D16 -> -15
B17: ='Key Assumptions'!B26 -> Technology & Subscriptions | C17: ='Key Assumptions'!C26 -> 150 | D17: 150 | E17: =C17-D17 -> 0
B18: ='Key Assumptions'!B27 -> Dining & Entertainment | C18: ='Key Assumptions'!C27 -> 250 | D18: 305 | E18: =C18-D18 -> -55
B19: ='Key Assumptions'!B28 -> Minimum Debt Obligations | C19: ='Key Assumptions'!C28 -> 765 | D19: 765 | E19: =C19-D19 -> 0
B20: ='Key Assumptions'!B29 -> Miscellaneous | C20: ='Key Assumptions'!C29 -> 250 | D20: 255 | E20: =C20-D20 -> -5
B21: Total Monthly Expenses | C21: =SUM(C12:C20) -> 4615 | D21: =SUM(D12:D20) -> 4720 | E21: =C21-D21 -> -105
B23: Goal Allocations
B24: Category | C24: Budgeted Amount | D24: Actual Amount | E24: Variance
B25: Emergency Fund Contribution | C25: 500 | D25: 500 | E25: =C25-D25 -> 0
B26: Retirement Contribution | C26: 0 | D26: 0 | E26: =C26-D26 -> 0
B27: Extra Debt Payment | C27: 150 | D27: 150 | E27: =C27-D27 -> 0
B28: Other Savings | C28: 0 | D28: 0 | E28: =C28-D28 -> 0
B29: Total Goal Allocations | C29: =SUM(C25:C28) -> 650 | D29: =SUM(D25:D28) -> 650 | E29: =C29-D29 -> 0
B31: Cash Flow Summary
B32: Total Monthly Net Income | C32: =D8 -> 5408.33
B33: Total Monthly Expenses | C33: =D21 -> 4720
B34: Total Goal Allocations | C34: =D29 -> 650
B35: Monthly Surplus/Deficit | C35: =D8-D21-D29 -> 38.33
B36: Savings Rate | C36: =(D25+D26+D28)/D8 -> 0.09244998
B37: Extra Debt Payment | C37: =D27 -> 150

Sheet Emergency Fund
B1: Emergency Fund
B2: ='Client Profile'!B2 -> Christopher Miller | C2: ='Client Profile'!C2 -> September 2026
B4: Overview
B5: Emergency Fund Month Target | C5: ='Key Assumptions'!C33 -> 3
B6: Emergency Fund Amount Target | C6: ='Key Assumptions'!C34 -> 14000
B7: Current Emergency Fund | C7: ='Financial Position'!D8 -> 2000
B8: Remaining Needed | C8: =C6-C7 -> 12000
B9: Monthly Contribution | C9: ='Key Assumptions'!C35 -> 500
B10: Current Progress | C10: =C7/C6 -> 0.14285714
B11: Projected Completion | C11: =B38 -> August 2028
B13: Saving Schedule
B14: Month | C14: Contribution | D14: Interest Earned | E14: Balance | F14: Remaining Needed | G14: Progress
B15: September 2026 | C15: 0 | D15: =2000*('Key Assumptions'!$C$47/12) -> 5.8333333 | E15: =2000+C15+D15 -> 2005.8333 | F15: =MAX(0,$C$6-E15) -> 11994.167 | G15: =MIN(1,E15/$C$6) -> 0.14327381
B16: October 2026 | C16: =$C$9 -> 500 | D16: =E15*('Key Assumptions'!$C$47/12) -> 5.8503472 | E16: =2000+C16+D16 -> 2505.8503 | F16: =MAX(0,$C$6-E16) -> 11494.15 | G16: =MIN(1,E16/$C$6) -> 0.17898931
B17: November 2026 | C17: =$C$9 -> 500 | D17: =E16*('Key Assumptions'!$C$47/12) -> 7.3087302 | E17: =E16+C17+D17 -> 3013.1591 | F17: =MAX(0,$C$6-E17) -> 10986.841 | G17: =MIN(1,E17/$C$6) -> 0.21522565
B18: December 2026 | C18: =$C$9 -> 500 | D18: =E17*('Key Assumptions'!$C$47/12) -> 8.7883806 | E18: =E17+C18+D18 -> 3521.9475 | F18: =MAX(0,$C$6-E18) -> 10478.053 | G18: =MIN(1,E18/$C$6) -> 0.25156768
B19: January 2027 | C19: =$C$9 -> 500 | D19: =E18*('Key Assumptions'!$C$47/12) -> 10.272347 | E19: =E18+C19+D19 -> 4032.2198 | F19: =MAX(0,$C$6-E19) -> 9967.7802 | G19: =MIN(1,E19/$C$6) -> 0.2880157
B20: February 2027 | C20: =$C$9 -> 500 | D20: =E19*('Key Assumptions'!$C$47/12) -> 11.760641 | E20: =E19+C20+D20 -> 4543.9804 | F20: =MAX(0,$C$6-E20) -> 9456.0196 | G20: =MIN(1,E20/$C$6) -> 0.32457003
B21: March 2027 | C21: =$C$9 -> 500 | D21: =E20*('Key Assumptions'!$C$47/12) -> 13.253276 | E21: =E20+C21+D21 -> 5057.2337 | F21: =MAX(0,$C$6-E21) -> 8942.7663 | G21: =MIN(1,E21/$C$6) -> 0.36123098
B22: April 2027 | C22: =$C$9 -> 500 | D22: =E21*('Key Assumptions'!$C$47/12) -> 14.750265 | E22: =E21+C22+D22 -> 5571.984 | F22: =MAX(0,$C$6-E22) -> 8428.016 | G22: =MIN(1,E22/$C$6) -> 0.39799886
B23: May 2027 | C23: =$C$9 -> 500 | D23: =E22*('Key Assumptions'!$C$47/12) -> 16.25162 | E23: =E22+C23+D23 -> 6088.2356 | F23: =MAX(0,$C$6-E23) -> 7911.7644 | G23: =MIN(1,E23/$C$6) -> 0.43487397
B24: June 2027 | C24: =$C$9 -> 500 | D24: =E23*('Key Assumptions'!$C$47/12) -> 17.757354 | E24: =E23+C24+D24 -> 6605.993 | F24: =MAX(0,$C$6-E24) -> 7394.007 | G24: =MIN(1,E24/$C$6) -> 0.47185664
B25: July 2027 | C25: =$C$9 -> 500 | D25: =E24*('Key Assumptions'!$C$47/12) -> 19.267479 | E25: =E24+C25+D25 -> 7125.2604 | F25: =MAX(0,$C$6-E25) -> 6874.7396 | G25: =MIN(1,E25/$C$6) -> 0.50894717
B26: August 2027 | C26: =$C$9 -> 500 | D26: =E25*('Key Assumptions'!$C$47/12) -> 20.78201 | E26: =E25+C26+D26 -> 7646.0425 | F26: =MAX(0,$C$6-E26) -> 6353.9575 | G26: =MIN(1,E26/$C$6) -> 0.54614589
B27: September 2027 | C27: =$C$9 -> 500 | D27: =E26*('Key Assumptions'!$C$47/12) -> 22.300957 | E27: =E26+C27+D27 -> 8168.3434 | F27: =MAX(0,$C$6-E27) -> 5831.6566 | G27: =MIN(1,E27/$C$6) -> 0.5834531
B28: October 2027 | C28: =$C$9 -> 500 | D28: =E27*('Key Assumptions'!$C$47/12) -> 23.824335 | E28: =E27+C28+D28 -> 8692.1677 | F28: =MAX(0,$C$6-E28) -> 5307.8323 | G28: =MIN(1,E28/$C$6) -> 0.62086912
... B38: August 2028 | C38: =$C$9 -> 500 | D38: =E37*('Key Assumptions'!$C$47/12) -> 39.304639 | E38: =E37+C38+D38 -> 14015.181 | F38: =MAX(0,$C$6-E38) -> 0 | G38: =MIN(1,E38/$C$6) -> 1

Sheet Debt Payoff
B1: Debt Payoff
B2: ='Client Profile'!B2 -> Christopher Miller | C2: ='Client Profile'!C2 -> September 2026
B4: Debt Payoff Overview
B5: Payoff Method | C5: Avalanche
B6: Total Starting Debt | C6: 34650
B7: Total Minimum Payments | C7: ='Financial Position'!F23 -> 765
B8: Extra Monthly Payment | C8: ='Cash-Flow & Budget'!C27 -> 150
B9: Total Monthly Payments | C9: ='Cash-Flow & Budget'!C27+'Financial Position'!F23 -> 915
B10: Target Debt-Free Date | C10: =C31 -> January 2030
B11: Projected Total Interest | C11: =SUM(H35:H75) -> 6612.7538
B13: Debt Inventory & Priority Table
B14: Category | C14: Creditor | D14: Priority | E14: Current Balance | F14: APR | G14: Minimum Payment | H14: Extra Payment | I14: Total Payment
B15: ='Financial Position'!B18 -> Credit Card | C15: ='Financial Position'!C18 -> Chase | D15: 1 | E15: ='Financial Position'!D18 -> 5400 | F15: ='Financial Position'!E18 -> 0.2724 | G15: ='Financial Position'!F18 -> 165 | H15: 150 | I15: =G15+H15 -> 315
B16: ='Financial Position'!B19 -> Credit Card | C16: ='Financial Position'!C19 -> Discover | D16: 2 | E16: ='Financial Position'!D19 -> 3100 | F16: ='Financial Position'!E19 -> 0.2499 | G16: ='Financial Position'!F19 -> 95 | H16: 0 | I16: =G16+H16 -> 95
B17: ='Financial Position'!B20 -> Credit Card | C17: ='Financial Position'!C20 -> Capital One | D17: 3 | E17: ='Financial Position'!D20 -> 1850 | F17: ='Financial Position'!E20 -> 0.2299 | G17: ='Financial Position'!F20 -> 60 | H17: 0 | I17: =G17+H17 -> 60
B18: ='Financial Position'!B22 -> Auto Loan | C18: ='Financial Position'!C22 -> Wells Fargo | D18: 4 | E18: ='Financial Position'!D22 -> 9800 | F18: ='Financial Position'!E22 -> 0.0649 | G18: ='Financial Position'!F22 -> 285 | H18: 0 | I18: =G18+H18 -> 285
B19: ='Financial Position'!B21 -> Student Loan | C19: ='Financial Position'!C21 -> Aidvantage | D19: 5 | E19: ='Financial Position'!D21 -> 14500 | F19: ='Financial Position'!E21 -> 0.0525 | G19: ='Financial Position'!F21 -> 160 | H19: 0 | I19: =G19+H19 -> 160
B20: Total | E20: =SUM(E15:E19) -> 34650 | G20: =SUM(G15:G19) -> 765 | H20: =SUM(H15:H19) -> 150 | I20: =SUM(I15:I19) -> 915
B22: Progress Milestones
B23: Milestone | C23: Projected Date | D23: Total Remaining Debt
B24: 25% Paid Off | C24: =B49 -> November 2027 | D24: =I35*0.75 -> 25987.5
B25: First Debt Paid Off | C25: =B57 -> July 2028 | D25: =I57 -> 20117.746
B26: 50% Paid Off | C26: =B61 -> November 2028 | D26: =I35*0.5 -> 17325
B27: Second Debt Paid Off | C27: =B61 -> November 2028 | D27: =I63 -> 14437.094
B28: Third Debt Paid Off | C28: =B63 -> January 2029 | D28: =I66 -> 11301.55
B29: Fourth Debt Paid Off | C29: =B66 -> April 2029 | D29: =I69 -> 6079.3084
B30: 75% Paid Off | C30: =B72 -> October 2029 | D30: =I35*0.25 -> 8662.5
B31: Debt Free | C31: =B75 -> January 2030 | D31: =I75 -> 0
B33: Payoff Schedule
B34: Month | C34: Chase Card Balance | D34: Discover Card Balance | E34: Capital One Card Balance | F34: Auto Loan Balance | G34: Student Loan Balance | H34: Monthly Interest Accrued | I34: Total Remaining Debt
B35: September 2026 | C35: 5400 | D35: 3100 | E35: 1850 | F35: 9800 | G35: 14500 | H35: =SUM((C35*($F$15/12))+(D35*($F$16/12))+(E35*($F$17/12))+(F35*($F$18/12))+(G35*($F$19/12))) -> 339.01958 | I35: =SUM(C35:G35) -> 34650
B36: October 2026 | C36: =MAX(0,C35*(1+$F$15/12)-($I$15)) -> 5207.58 | D36: =MAX(0,D35*(1+$F$16/12)-($I$16)) -> 3069.5575 | E36: =MAX(0,E35*(1+$F$17/12)-($I$17)) -> 1825.4429 | F36: =MAX(0,F35*(1+$F$18/12)-($I$18)) -> 9568.0017 | G36: =MAX(0,G35*(1+$F$19/12)-($I$19)) -> 14403.438 | H36: =SUM((C36*($F$15/12))+(D36*($F$16/12))+(E36*($F$17/12))+(F36*($F$18/12))+(G36*($F$19/12))) -> 331.87003 | I36: =SUM(C36:G36) -> 34074.02
B37: November 2026 | C37: =MAX(0,C36*(1+$F$15/12)-($I$15)) -> 5010.7921 | D37: =MAX(0,D36*(1+$F$16/12)-($I$16)) -> 3038.481 | E37: =MAX(0,E36*(1+$F$17/12)-($I$17)) -> 1800.4154 | F37: =MAX(0,F36*(1+$F$18/12)-($I$18)) -> 9334.7486 | G37: =MAX(0,G36*(1+$F$19/12)-($I$19)) -> 14306.453 | H37: =SUM((C37*($F$15/12))+(D37*($F$16/12))+(E37*($F$17/12))+(F37*($F$18/12))+(G37*($F$19/12))) -> 324.59047 | I37: =SUM(C37:G37) -> 33490.89
B38: December 2026 | C38: =MAX(0,C37*(1+$F$15/12)-($I$15)) -> 4809.537 | D38: =MAX(0,D37*(1+$F$16/12)-($I$16)) -> 3006.7574 | E38: =MAX(0,E37*(1+$F$17/12)-($I$17)) -> 1774.9083 | F38: =MAX(0,F37*(1+$F$18/12)-($I$18)) -> 9100.234 | G38: =MAX(0,G37*(1+$F$19/12)-($I$19)) -> 14209.043 | H38: =SUM((C38*($F$15/12))+(D38*($F$16/12))+(E38*($F$17/12))+(F38*($F$18/12))+(G38*($F$19/12))) -> 317.17816 | I38: =SUM(C38:G38) -> 32900.48
B39: January 2027 | C39: =MAX(0,C38*(1+$F$15/12)-($I$15)) -> 4603.7135 | D39: =MAX(0,D38*(1+$F$16/12)-($I$16)) -> 2974.3731 | E39: =MAX(0,E38*(1+$F$17/12)-($I$17)) -> 1748.9126 | F39: =MAX(0,F38*(1+$F$18/12)-($I$18)) -> 8864.4511 | G39: =MAX(0,G38*(1+$F$19/12)-($I$19)) -> 14111.208 | H39: =SUM((C39*($F$15/12))+(D39*($F$16/12))+(E39*($F$17/12))+(F39*($F$18/12))+(G39*($F$19/12))) -> 309.63031 | I39: =SUM(C39:G39) -> 32302.658
B40: February 2027 | C40: =MAX(0,C39*(1+$F$15/12)-($I$15)) -> 4393.2178 | D40: =MAX(0,D39*(1+$F$16/12)-($I$16)) -> 2941.3144 | E40: =MAX(0,E39*(1+$F$17/12)-($I$17)) -> 1722.4189 | F40: =MAX(0,F39*(1+$F$18/12)-($I$18)) -> 8627.393 | G40: =MAX(0,G39*(1+$F$19/12)-($I$19)) -> 14012.944 | H40: =SUM((C40*($F$15/12))+(D40*($F$16/12))+(E40*($F$17/12))+(F40*($F$18/12))+(G40*($F$19/12))) -> 301.94404 | I40: =SUM(C40:G40) -> 31697.289
B41: March 2027 | C41: =MAX(0,C40*(1+$F$15/12)-($I$15)) -> 4177.9439 | D41: =MAX(0,D40*(1+$F$16/12)-($I$16)) -> 2907.5673 | E41: =MAX(0,E40*(1+$F$17/12)-($I$17)) -> 1695.4175 | F41: =MAX(0,F40*(1+$F$18/12)-($I$18)) -> 8389.0529 | G41: =MAX(0,G40*(1+$F$19/12)-($I$19)) -> 13914.251 | H41: =SUM((C41*($F$15/12))+(D41*($F$16/12))+(E41*($F$17/12))+(F41*($F$18/12))+(G41*($F$19/12))) -> 294.11643 | I41: =SUM(C41:G41) -> 31084.233
B42: April 2027 | C42: =MAX(0,C41*(1+$F$15/12)-($I$15)) -> 3957.7832 | D42: =MAX(0,D41*(1+$F$16/12)-($I$16)) -> 2873.1174 | E42: =MAX(0,E41*(1+$F$17/12)-($I$17)) -> 1667.8989 | F42: =MAX(0,F41*(1+$F$18/12)-($I$18)) -> 8149.4237 | G42: =MAX(0,G41*(1+$F$19/12)-($I$19)) -> 13815.126 | H42: =SUM((C42*($F$15/12))+(D42*($F$16/12))+(E42*($F$17/12))+(F42*($F$18/12))+(G42*($F$19/12))) -> 286.14449 | I42: =SUM(C42:G42) -> 30463.349
B43: May 2027 | C43: =MAX(0,C42*(1+$F$15/12)-($I$15)) -> 3732.6249 | D43: =MAX(0,D42*(1+$F$16/12)-($I$16)) -> 2837.9501 | E43: =MAX(0,E42*(1+$F$17/12)-($I$17)) -> 1639.8531 | F43: =MAX(0,F42*(1+$F$18/12)-($I$18)) -> 7908.4985 | G43: =MAX(0,G42*(1+$F$19/12)-($I$19)) -> 13715.567 | H43: =SUM((C43*($F$15/12))+(D43*($F$16/12))+(E43*($F$17/12))+(F43*($F$18/12))+(G43*($F$19/12))) -> 278.02515 | I43: =SUM(C43:G43) -> 29834.494
B44: June 2027 | C44: =MAX(0,C43*(1+$F$15/12)-($I$15)) -> 3502.3555 | D44: =MAX(0,D43*(1+$F$16/12)-($I$16)) -> 2802.0504 | E44: =MAX(0,E43*(1+$F$17/12)-($I$17)) -> 1611.2699 | F44: =MAX(0,F43*(1+$F$18/12)-($I$18)) -> 7666.2703 | G44: =MAX(0,G43*(1+$F$19/12)-($I$19)) -> 13615.573 | H44: =SUM((C44*($F$15/12))+(D44*($F$16/12))+(E44*($F$17/12))+(F44*($F$18/12))+(G44*($F$19/12))) -> 269.75529 | I44: =SUM(C44:G44) -> 29197.519
...

Sheet Planning Dashboard
B1: Planning Dashboard
B2: ='Client Profile'!B2 -> Christopher Miller | C2: ='Client Profile'!C2 -> September 2026
B4: Priority: Establish an emergency fund while eliminating debt
B6: KPIs
B7: Net Worth | C7: Total Debt | D7: Monthly Surplus/Deficit | E7: Savings Rate | F7: Emergency Fund Progress | G7: Projected Debt-Free Date
B8: ='Financial Position'!C28 -> -4600 | C8: ='Debt Payoff'!E20 -> 34650 | D8: ='Cash-Flow & Budget'!C35 -> 38.33 | E8: ='Cash-Flow & Budget'!C36 -> 0.09244998 | F8: ='Financial Position'!D8/'Key Assumptions'!C34 -> 0.14285714 | G8: ='Debt Payoff'!C10 -> January 2030
B23: Top Actions
B24: 1. Build the emergency fund to the target level by allocating $500 per month.
B25: 2. Use all designated extra cash toward highest interest under the debt-avalanche strategy.
B26: 3. Maintain retirement contributions only at the planned level until debt is repaid, then redirect the released payment to retirement.
